[2025-05-02T02:28:51.037+0000] {taskinstance.py:1125} INFO - Dependencies all met for dep_context=non-requeueable deps ti=<TaskInstance: Pipeline-proyecto2.load_transformed_data manual__2025-05-02T02:28:14.976219+00:00 [queued]>
[2025-05-02T02:28:51.049+0000] {taskinstance.py:1125} INFO - Dependencies all met for dep_context=requeueable deps ti=<TaskInstance: Pipeline-proyecto2.load_transformed_data manual__2025-05-02T02:28:14.976219+00:00 [queued]>
[2025-05-02T02:28:51.049+0000] {taskinstance.py:1331} INFO - Starting attempt 1 of 1
[2025-05-02T02:28:51.068+0000] {taskinstance.py:1350} INFO - Executing <Task(PythonOperator): load_transformed_data> on 2025-05-02 02:28:14.976219+00:00
[2025-05-02T02:28:51.085+0000] {standard_task_runner.py:57} INFO - Started process 97 to run task
[2025-05-02T02:28:51.092+0000] {standard_task_runner.py:84} INFO - Running: ['***', 'tasks', 'run', 'Pipeline-proyecto2', 'load_transformed_data', 'manual__2025-05-02T02:28:14.976219+00:00', '--job-id', '6', '--raw', '--subdir', 'DAGS_FOLDER/dag-proyecto2.py', '--cfg-path', '/tmp/tmpgpxtlwkz']
[2025-05-02T02:28:51.097+0000] {standard_task_runner.py:85} INFO - Job 6: Subtask load_transformed_data
[2025-05-02T02:28:51.197+0000] {task_command.py:410} INFO - Running <TaskInstance: Pipeline-proyecto2.load_transformed_data manual__2025-05-02T02:28:14.976219+00:00 [running]> on host 5b68dcb6aec6
[2025-05-02T02:28:51.309+0000] {taskinstance.py:1568} INFO - Exporting env vars: AIRFLOW_CTX_DAG_OWNER='***' AIRFLOW_CTX_DAG_ID='Pipeline-proyecto2' AIRFLOW_CTX_TASK_ID='load_transformed_data' AIRFLOW_CTX_EXECUTION_DATE='2025-05-02T02:28:14.976219+00:00' AIRFLOW_CTX_TRY_NUMBER='1' AIRFLOW_CTX_DAG_RUN_ID='manual__2025-05-02T02:28:14.976219+00:00'
[2025-05-02T02:29:04.148+0000] {taskinstance.py:1847} ERROR - Task failed with exception
Traceback (most recent call last):
  File "/home/airflow/.local/lib/python3.9/site-packages/airflow/operators/python.py", line 181, in execute
    return_value = self.execute_callable()
  File "/home/airflow/.local/lib/python3.9/site-packages/airflow/operators/python.py", line 198, in execute_callable
    return self.python_callable(*self.op_args, **self.op_kwargs)
  File "/opt/airflow/dags/dag-proyecto2.py", line 77, in preprocesamiento
    X_train.to_sql("train_data_X", con=engine, if_exists="replace", index=False)
NameError: name 'engine' is not defined
[2025-05-02T02:29:04.160+0000] {taskinstance.py:1368} INFO - Marking task as FAILED. dag_id=Pipeline-proyecto2, task_id=load_transformed_data, execution_date=20250502T022814, start_date=20250502T022851, end_date=20250502T022904
[2025-05-02T02:29:04.176+0000] {standard_task_runner.py:104} ERROR - Failed to execute job 6 for task load_transformed_data (name 'engine' is not defined; 97)
[2025-05-02T02:29:04.235+0000] {local_task_job_runner.py:232} INFO - Task exited with return code 1
[2025-05-02T02:29:04.279+0000] {taskinstance.py:2674} INFO - 0 downstream tasks scheduled from follow-on schedule check
