[2025-05-05T09:43:46.408+0000] {taskinstance.py:1125} INFO - Dependencies all met for dep_context=non-requeueable deps ti=<TaskInstance: Pipeline-proyecto2.training_with_gradient_boosting_model manual__2025-05-05T09:42:35.480064+00:00 [queued]>
[2025-05-05T09:43:46.448+0000] {taskinstance.py:1125} INFO - Dependencies all met for dep_context=requeueable deps ti=<TaskInstance: Pipeline-proyecto2.training_with_gradient_boosting_model manual__2025-05-05T09:42:35.480064+00:00 [queued]>
[2025-05-05T09:43:46.448+0000] {taskinstance.py:1331} INFO - Starting attempt 1 of 1
[2025-05-05T09:43:46.494+0000] {taskinstance.py:1350} INFO - Executing <Task(PythonOperator): training_with_gradient_boosting_model> on 2025-05-05 09:42:35.480064+00:00
[2025-05-05T09:43:46.546+0000] {standard_task_runner.py:57} INFO - Started process 114 to run task
[2025-05-05T09:43:46.594+0000] {standard_task_runner.py:84} INFO - Running: ['***', 'tasks', 'run', 'Pipeline-proyecto2', 'training_with_gradient_boosting_model', 'manual__2025-05-05T09:42:35.480064+00:00', '--job-id', '45', '--raw', '--subdir', 'DAGS_FOLDER/dag-proyecto2.py', '--cfg-path', '/tmp/tmpx8nk8ypa']
[2025-05-05T09:43:46.643+0000] {standard_task_runner.py:85} INFO - Job 45: Subtask training_with_gradient_boosting_model
[2025-05-05T09:43:47.124+0000] {task_command.py:410} INFO - Running <TaskInstance: Pipeline-proyecto2.training_with_gradient_boosting_model manual__2025-05-05T09:42:35.480064+00:00 [running]> on host 3ebc3f4fce7e
[2025-05-05T09:43:47.828+0000] {taskinstance.py:1568} INFO - Exporting env vars: AIRFLOW_CTX_DAG_OWNER='***' AIRFLOW_CTX_DAG_ID='Pipeline-proyecto2' AIRFLOW_CTX_TASK_ID='training_with_gradient_boosting_model' AIRFLOW_CTX_EXECUTION_DATE='2025-05-05T09:42:35.480064+00:00' AIRFLOW_CTX_TRY_NUMBER='1' AIRFLOW_CTX_DAG_RUN_ID='manual__2025-05-05T09:42:35.480064+00:00'
[2025-05-05T09:43:55.728+0000] {connectionpool.py:812} WARNING - Retrying (Retry(total=4, connect=4, read=5, redirect=5, status=5)) after connection broken by 'NewConnectionError('<urllib3.connection.HTTPConnection object at 0x7df86b5bca90>: Failed to establish a new connection: [Errno -3] Temporary failure in name resolution')': /api/2.0/mlflow/experiments/get-by-name?experiment_name=Gradient_Boosting_looking_for_the_best_model
[2025-05-05T09:43:59.736+0000] {connectionpool.py:812} WARNING - Retrying (Retry(total=3, connect=3, read=5, redirect=5, status=5)) after connection broken by 'NewConnectionError('<urllib3.connection.HTTPConnection object at 0x7df86b5bc340>: Failed to establish a new connection: [Errno -3] Temporary failure in name resolution')': /api/2.0/mlflow/experiments/get-by-name?experiment_name=Gradient_Boosting_looking_for_the_best_model
[2025-05-05T09:44:07.754+0000] {connectionpool.py:812} WARNING - Retrying (Retry(total=2, connect=2, read=5, redirect=5, status=5)) after connection broken by 'NewConnectionError('<urllib3.connection.HTTPConnection object at 0x7df86b5bcca0>: Failed to establish a new connection: [Errno -3] Temporary failure in name resolution')': /api/2.0/mlflow/experiments/get-by-name?experiment_name=Gradient_Boosting_looking_for_the_best_model
[2025-05-05T09:44:23.777+0000] {connectionpool.py:812} WARNING - Retrying (Retry(total=1, connect=1, read=5, redirect=5, status=5)) after connection broken by 'NewConnectionError('<urllib3.connection.HTTPConnection object at 0x7df86b5bc9d0>: Failed to establish a new connection: [Errno -3] Temporary failure in name resolution')': /api/2.0/mlflow/experiments/get-by-name?experiment_name=Gradient_Boosting_looking_for_the_best_model
[2025-05-05T09:44:55.818+0000] {connectionpool.py:812} WARNING - Retrying (Retry(total=0, connect=0, read=5, redirect=5, status=5)) after connection broken by 'NewConnectionError('<urllib3.connection.HTTPConnection object at 0x7df869e35820>: Failed to establish a new connection: [Errno -3] Temporary failure in name resolution')': /api/2.0/mlflow/experiments/get-by-name?experiment_name=Gradient_Boosting_looking_for_the_best_model
[2025-05-05T09:44:55.831+0000] {taskinstance.py:1847} ERROR - Task failed with exception
Traceback (most recent call last):
  File "/home/airflow/.local/lib/python3.9/site-packages/urllib3/connection.py", line 174, in _new_conn
    conn = connection.create_connection(
  File "/home/airflow/.local/lib/python3.9/site-packages/urllib3/util/connection.py", line 72, in create_connection
    for res in socket.getaddrinfo(host, port, family, socket.SOCK_STREAM):
  File "/usr/local/lib/python3.9/socket.py", line 954, in getaddrinfo
    for res in _socket.getaddrinfo(host, port, family, type, proto, flags):
socket.gaierror: [Errno -3] Temporary failure in name resolution

During handling of the above exception, another exception occurred:

Traceback (most recent call last):
  File "/home/airflow/.local/lib/python3.9/site-packages/urllib3/connectionpool.py", line 703, in urlopen
    httplib_response = self._make_request(
  File "/home/airflow/.local/lib/python3.9/site-packages/urllib3/connectionpool.py", line 398, in _make_request
    conn.request(method, url, **httplib_request_kw)
  File "/home/airflow/.local/lib/python3.9/site-packages/urllib3/connection.py", line 244, in request
    super(HTTPConnection, self).request(method, url, body=body, headers=headers)
  File "/usr/local/lib/python3.9/http/client.py", line 1285, in request
    self._send_request(method, url, body, headers, encode_chunked)
  File "/usr/local/lib/python3.9/http/client.py", line 1331, in _send_request
    self.endheaders(body, encode_chunked=encode_chunked)
  File "/usr/local/lib/python3.9/http/client.py", line 1280, in endheaders
    self._send_output(message_body, encode_chunked=encode_chunked)
  File "/usr/local/lib/python3.9/http/client.py", line 1040, in _send_output
    self.send(msg)
  File "/usr/local/lib/python3.9/http/client.py", line 980, in send
    self.connect()
  File "/home/airflow/.local/lib/python3.9/site-packages/urllib3/connection.py", line 205, in connect
    conn = self._new_conn()
  File "/home/airflow/.local/lib/python3.9/site-packages/urllib3/connection.py", line 186, in _new_conn
    raise NewConnectionError(
urllib3.exceptions.NewConnectionError: <urllib3.connection.HTTPConnection object at 0x7df869e35490>: Failed to establish a new connection: [Errno -3] Temporary failure in name resolution

During handling of the above exception, another exception occurred:

Traceback (most recent call last):
  File "/home/airflow/.local/lib/python3.9/site-packages/requests/adapters.py", line 489, in send
    resp = conn.urlopen(
  File "/home/airflow/.local/lib/python3.9/site-packages/urllib3/connectionpool.py", line 815, in urlopen
    return self.urlopen(
  File "/home/airflow/.local/lib/python3.9/site-packages/urllib3/connectionpool.py", line 815, in urlopen
    return self.urlopen(
  File "/home/airflow/.local/lib/python3.9/site-packages/urllib3/connectionpool.py", line 815, in urlopen
    return self.urlopen(
  [Previous line repeated 2 more times]
  File "/home/airflow/.local/lib/python3.9/site-packages/urllib3/connectionpool.py", line 787, in urlopen
    retries = retries.increment(
  File "/home/airflow/.local/lib/python3.9/site-packages/urllib3/util/retry.py", line 592, in increment
    raise MaxRetryError(_pool, url, error or ResponseError(cause))
urllib3.exceptions.MaxRetryError: HTTPConnectionPool(host='mlflow-service', port=5000): Max retries exceeded with url: /api/2.0/mlflow/experiments/get-by-name?experiment_name=Gradient_Boosting_looking_for_the_best_model (Caused by NewConnectionError('<urllib3.connection.HTTPConnection object at 0x7df869e35490>: Failed to establish a new connection: [Errno -3] Temporary failure in name resolution'))

During handling of the above exception, another exception occurred:

Traceback (most recent call last):
  File "/home/airflow/.local/lib/python3.9/site-packages/mlflow/utils/rest_utils.py", line 174, in http_request
    return _get_http_response_with_retries(
  File "/home/airflow/.local/lib/python3.9/site-packages/mlflow/utils/rest_utils.py", line 105, in _get_http_response_with_retries
    return session.request(method, url, **kwargs)
  File "/home/airflow/.local/lib/python3.9/site-packages/requests/sessions.py", line 587, in request
    resp = self.send(prep, **send_kwargs)
  File "/home/airflow/.local/lib/python3.9/site-packages/requests/sessions.py", line 701, in send
    r = adapter.send(request, **kwargs)
  File "/home/airflow/.local/lib/python3.9/site-packages/requests/adapters.py", line 565, in send
    raise ConnectionError(e, request=request)
requests.exceptions.ConnectionError: HTTPConnectionPool(host='mlflow-service', port=5000): Max retries exceeded with url: /api/2.0/mlflow/experiments/get-by-name?experiment_name=Gradient_Boosting_looking_for_the_best_model (Caused by NewConnectionError('<urllib3.connection.HTTPConnection object at 0x7df869e35490>: Failed to establish a new connection: [Errno -3] Temporary failure in name resolution'))

During handling of the above exception, another exception occurred:

Traceback (most recent call last):
  File "/home/airflow/.local/lib/python3.9/site-packages/airflow/operators/python.py", line 181, in execute
    return_value = self.execute_callable()
  File "/home/airflow/.local/lib/python3.9/site-packages/airflow/operators/python.py", line 198, in execute_callable
    return self.python_callable(*self.op_args, **self.op_kwargs)
  File "/opt/airflow/dags/dag-proyecto2.py", line 195, in entrenamiento_gradient_boosting
    mlflow.set_experiment("Gradient_Boosting_looking_for_the_best_model")
  File "/home/airflow/.local/lib/python3.9/site-packages/mlflow/tracking/fluent.py", line 113, in set_experiment
    experiment = client.get_experiment_by_name(experiment_name)
  File "/home/airflow/.local/lib/python3.9/site-packages/mlflow/tracking/client.py", line 461, in get_experiment_by_name
    return self._tracking_client.get_experiment_by_name(name)
  File "/home/airflow/.local/lib/python3.9/site-packages/mlflow/tracking/_tracking_service/client.py", line 220, in get_experiment_by_name
    return self.store.get_experiment_by_name(name)
  File "/home/airflow/.local/lib/python3.9/site-packages/mlflow/store/tracking/rest_store.py", line 304, in get_experiment_by_name
    response_proto = self._call_endpoint(GetExperimentByName, req_body)
  File "/home/airflow/.local/lib/python3.9/site-packages/mlflow/store/tracking/rest_store.py", line 56, in _call_endpoint
    return call_endpoint(self.get_host_creds(), endpoint, method, json_body, response_proto)
  File "/home/airflow/.local/lib/python3.9/site-packages/mlflow/utils/rest_utils.py", line 283, in call_endpoint
    response = http_request(
  File "/home/airflow/.local/lib/python3.9/site-packages/mlflow/utils/rest_utils.py", line 192, in http_request
    raise MlflowException(f"API request to {url} failed with exception {e}")
mlflow.exceptions.MlflowException: API request to http://mlflow-service:5000/api/2.0/mlflow/experiments/get-by-name failed with exception HTTPConnectionPool(host='mlflow-service', port=5000): Max retries exceeded with url: /api/2.0/mlflow/experiments/get-by-name?experiment_name=Gradient_Boosting_looking_for_the_best_model (Caused by NewConnectionError('<urllib3.connection.HTTPConnection object at 0x7df869e35490>: Failed to establish a new connection: [Errno -3] Temporary failure in name resolution'))
[2025-05-05T09:44:55.854+0000] {taskinstance.py:1368} INFO - Marking task as FAILED. dag_id=Pipeline-proyecto2, task_id=training_with_gradient_boosting_model, execution_date=20250505T094235, start_date=20250505T094346, end_date=20250505T094455
[2025-05-05T09:44:55.877+0000] {standard_task_runner.py:104} ERROR - Failed to execute job 45 for task training_with_gradient_boosting_model (API request to http://mlflow-service:5000/api/2.0/mlflow/experiments/get-by-name failed with exception HTTPConnectionPool(host='mlflow-service', port=5000): Max retries exceeded with url: /api/2.0/mlflow/experiments/get-by-name?experiment_name=Gradient_Boosting_looking_for_the_best_model (Caused by NewConnectionError('<urllib3.connection.HTTPConnection object at 0x7df869e35490>: Failed to establish a new connection: [Errno -3] Temporary failure in name resolution')); 114)
[2025-05-05T09:44:55.934+0000] {local_task_job_runner.py:232} INFO - Task exited with return code 1
[2025-05-05T09:44:55.979+0000] {taskinstance.py:2674} INFO - 0 downstream tasks scheduled from follow-on schedule check
