[2025-03-28T05:23:33.397+0000] {taskinstance.py:1125} INFO - Dependencies all met for dep_context=non-requeueable deps ti=<TaskInstance: Pipeline-proyecto2.load_raw_csv manual__2025-03-28T05:23:28.686074+00:00 [queued]>
[2025-03-28T05:23:33.412+0000] {taskinstance.py:1125} INFO - Dependencies all met for dep_context=requeueable deps ti=<TaskInstance: Pipeline-proyecto2.load_raw_csv manual__2025-03-28T05:23:28.686074+00:00 [queued]>
[2025-03-28T05:23:33.412+0000] {taskinstance.py:1331} INFO - Starting attempt 1 of 1
[2025-03-28T05:23:33.423+0000] {taskinstance.py:1350} INFO - Executing <Task(PythonOperator): load_raw_csv> on 2025-03-28 05:23:28.686074+00:00
[2025-03-28T05:23:33.438+0000] {standard_task_runner.py:57} INFO - Started process 112 to run task
[2025-03-28T05:23:33.442+0000] {standard_task_runner.py:84} INFO - Running: ['***', 'tasks', 'run', 'Pipeline-proyecto2', 'load_raw_csv', 'manual__2025-03-28T05:23:28.686074+00:00', '--job-id', '52', '--raw', '--subdir', 'DAGS_FOLDER/dag-proyecto2.py', '--cfg-path', '/tmp/tmpcsz5w37c']
[2025-03-28T05:23:33.445+0000] {standard_task_runner.py:85} INFO - Job 52: Subtask load_raw_csv
[2025-03-28T05:23:33.501+0000] {task_command.py:410} INFO - Running <TaskInstance: Pipeline-proyecto2.load_raw_csv manual__2025-03-28T05:23:28.686074+00:00 [running]> on host 031e5acb875a
[2025-03-28T05:23:33.590+0000] {taskinstance.py:1568} INFO - Exporting env vars: AIRFLOW_CTX_DAG_OWNER='***' AIRFLOW_CTX_DAG_ID='Pipeline-proyecto2' AIRFLOW_CTX_TASK_ID='load_raw_csv' AIRFLOW_CTX_EXECUTION_DATE='2025-03-28T05:23:28.686074+00:00' AIRFLOW_CTX_TRY_NUMBER='1' AIRFLOW_CTX_DAG_RUN_ID='manual__2025-03-28T05:23:28.686074+00:00'
[2025-03-28T05:23:33.724+0000] {taskinstance.py:1847} ERROR - Task failed with exception
Traceback (most recent call last):
  File "/home/airflow/.local/lib/python3.9/site-packages/urllib3/connection.py", line 174, in _new_conn
    conn = connection.create_connection(
  File "/home/airflow/.local/lib/python3.9/site-packages/urllib3/util/connection.py", line 72, in create_connection
    for res in socket.getaddrinfo(host, port, family, socket.SOCK_STREAM):
  File "/usr/local/lib/python3.9/socket.py", line 954, in getaddrinfo
    for res in _socket.getaddrinfo(host, port, family, type, proto, flags):
socket.gaierror: [Errno -2] Name or service not known

During handling of the above exception, another exception occurred:

Traceback (most recent call last):
  File "/home/airflow/.local/lib/python3.9/site-packages/urllib3/connectionpool.py", line 703, in urlopen
    httplib_response = self._make_request(
  File "/home/airflow/.local/lib/python3.9/site-packages/urllib3/connectionpool.py", line 398, in _make_request
    conn.request(method, url, **httplib_request_kw)
  File "/home/airflow/.local/lib/python3.9/site-packages/urllib3/connection.py", line 244, in request
    super(HTTPConnection, self).request(method, url, body=body, headers=headers)
  File "/usr/local/lib/python3.9/http/client.py", line 1285, in request
    self._send_request(method, url, body, headers, encode_chunked)
  File "/usr/local/lib/python3.9/http/client.py", line 1331, in _send_request
    self.endheaders(body, encode_chunked=encode_chunked)
  File "/usr/local/lib/python3.9/http/client.py", line 1280, in endheaders
    self._send_output(message_body, encode_chunked=encode_chunked)
  File "/usr/local/lib/python3.9/http/client.py", line 1040, in _send_output
    self.send(msg)
  File "/usr/local/lib/python3.9/http/client.py", line 980, in send
    self.connect()
  File "/home/airflow/.local/lib/python3.9/site-packages/urllib3/connection.py", line 205, in connect
    conn = self._new_conn()
  File "/home/airflow/.local/lib/python3.9/site-packages/urllib3/connection.py", line 186, in _new_conn
    raise NewConnectionError(
urllib3.exceptions.NewConnectionError: <urllib3.connection.HTTPConnection object at 0x7d5b6cdbff70>: Failed to establish a new connection: [Errno -2] Name or service not known

During handling of the above exception, another exception occurred:

Traceback (most recent call last):
  File "/home/airflow/.local/lib/python3.9/site-packages/requests/adapters.py", line 489, in send
    resp = conn.urlopen(
  File "/home/airflow/.local/lib/python3.9/site-packages/urllib3/connectionpool.py", line 787, in urlopen
    retries = retries.increment(
  File "/home/airflow/.local/lib/python3.9/site-packages/urllib3/util/retry.py", line 592, in increment
    raise MaxRetryError(_pool, url, error or ResponseError(cause))
urllib3.exceptions.MaxRetryError: HTTPConnectionPool(host='host.docker.internal', port=80): Max retries exceeded with url: /restart_data_generation?group_number=2 (Caused by NewConnectionError('<urllib3.connection.HTTPConnection object at 0x7d5b6cdbff70>: Failed to establish a new connection: [Errno -2] Name or service not known'))

During handling of the above exception, another exception occurred:

Traceback (most recent call last):
  File "/home/airflow/.local/lib/python3.9/site-packages/airflow/operators/python.py", line 181, in execute
    return_value = self.execute_callable()
  File "/home/airflow/.local/lib/python3.9/site-packages/airflow/operators/python.py", line 198, in execute_callable
    return self.python_callable(*self.op_args, **self.op_kwargs)
  File "/opt/airflow/dags/dag-proyecto2.py", line 40, in load_data
    requests.get('http://host.docker.internal/restart_data_generation?group_number=2')
  File "/home/airflow/.local/lib/python3.9/site-packages/requests/api.py", line 73, in get
    return request("get", url, params=params, **kwargs)
  File "/home/airflow/.local/lib/python3.9/site-packages/requests/api.py", line 59, in request
    return session.request(method=method, url=url, **kwargs)
  File "/home/airflow/.local/lib/python3.9/site-packages/requests/sessions.py", line 587, in request
    resp = self.send(prep, **send_kwargs)
  File "/home/airflow/.local/lib/python3.9/site-packages/requests/sessions.py", line 701, in send
    r = adapter.send(request, **kwargs)
  File "/home/airflow/.local/lib/python3.9/site-packages/requests/adapters.py", line 565, in send
    raise ConnectionError(e, request=request)
requests.exceptions.ConnectionError: HTTPConnectionPool(host='host.docker.internal', port=80): Max retries exceeded with url: /restart_data_generation?group_number=2 (Caused by NewConnectionError('<urllib3.connection.HTTPConnection object at 0x7d5b6cdbff70>: Failed to establish a new connection: [Errno -2] Name or service not known'))
[2025-03-28T05:23:33.748+0000] {taskinstance.py:1368} INFO - Marking task as FAILED. dag_id=Pipeline-proyecto2, task_id=load_raw_csv, execution_date=20250328T052328, start_date=20250328T052333, end_date=20250328T052333
[2025-03-28T05:23:33.764+0000] {standard_task_runner.py:104} ERROR - Failed to execute job 52 for task load_raw_csv (HTTPConnectionPool(host='host.docker.internal', port=80): Max retries exceeded with url: /restart_data_generation?group_number=2 (Caused by NewConnectionError('<urllib3.connection.HTTPConnection object at 0x7d5b6cdbff70>: Failed to establish a new connection: [Errno -2] Name or service not known')); 112)
[2025-03-28T05:23:33.815+0000] {local_task_job_runner.py:232} INFO - Task exited with return code 1
[2025-03-28T05:23:33.836+0000] {taskinstance.py:2674} INFO - 0 downstream tasks scheduled from follow-on schedule check
